Workbook

Sheet Summary
A1: SUMMARY — ANALISIS STATISTIK OVERTIME INDEX (Jan 2024 – Jun 2026)
A2: Seluruh angka pada sheet ini adalah link formula ke sheet Data, Korelasi Pearson, Regresi, dan Index Ideal. Ubah data di sheet Data → semua hasil ikut berubah.
A4: A. FLOW ANALISIS (urutan kerja)
A5: Tahap | B5: Aktivitas | C5: Penjelasan
A6: Langkah 1 | B6: Input & Validasi Data | C6: Sheet Data: 30 observasi bulanan (t=1..30), 3 variabel bebas (Hari Kerja, Volume Produksi, Man Power) dan 1 variabel terikat (Total Index Overtime) + statistik deskriptif.
A7: Langkah 2 | B7: Korelasi Pearson | C7: Mengukur arah & kekuatan hubungan tiap X terhadap Y (fungsi CORREL), lalu diuji signifikansinya dengan uji t: t = r√(n-2)/√(1-r²), P-Value = TDIST(|t|; df; 2).
A8: Langkah 3 | B8: Cek Multikolinearitas | C8: Korelasi antar prediktor diperiksa; r > 0,8 menandakan tumpang tindih informasi antar variabel bebas.
A9: Langkah 4 | B9: Regresi Linier Berganda | C9: LINEST(Y; X1:X3) di-unpack dengan INDEX untuk memperoleh koefisien, standard error, R², F, dan sum of squares — semuanya live formula.
A10: Langkah 5 | B10: Uji F (simultan) | C10: Menguji apakah model secara keseluruhan layak: F = MS Regresi / MS Residual, Sig. F = FDIST(F; k; n-k-1).
A11: Langkah 6 | B11: Uji t & P-Value (parsial) | C11: Menguji pengaruh masing-masing variabel: t = koefisien / std error, P-Value = TDIST(|t|; n-k-1; 2), plus interval keyakinan 95%.
A12: Langkah 7 | B12: Uji Asumsi Klasik | C12: Normalitas residual (Jarque-Bera), autokorelasi (Durbin-Watson), heteroskedastisitas (Glejser), dan multikolinearitas (VIF). Wajib dicek sebelum P-Value ditafsirkan, khususnya autokorelasi karena data berupa deret waktu bulanan.
A13: Langkah 8 | B13: Index Ideal | C13: Persamaan regresi dipakai menghitung level overtime wajar tiap bulan; dibandingkan aktual untuk melihat deviasi, lalu benchmark kuartil-1 dipakai sebagai target efisiensi.
A15: B. HASIL KORELASI PEARSON
A16: Variabel | B16: r | C16: r² (%) | D16: t-hitung | E16: P-Value | F16: Keputusan | G16: Interpretasi
A17: X1 - Jumlah Hari Kerja | B17: ='Korelasi Pearson'!B16 -> 0.065955224 | C17: ='Korelasi Pearson'!C16*100 -> 0.43500916 | D17: ='Korelasi Pearson'!D16 -> 0.34976382 | E17: ='Korelasi Pearson'!F16 -> 0.72913314 | F17: ='Korelasi Pearson'!G16 -> Tidak Signifikan (Terima H0) | G17: ='Korelasi Pearson'!H16 -> Sangat Lemah / Positif
A18: X2 - Volume Produksi | B18: ='Korelasi Pearson'!B17 -> 0.6370945 | C18: ='Korelasi Pearson'!C17*100 -> 40.588941 | D18: ='Korelasi Pearson'!D17 -> 4.3737024 | E18: ='Korelasi Pearson'!F17 -> 0.00015319005 | F18: ='Korelasi Pearson'!G17 -> Signifikan (Tolak H0) | G18: ='Korelasi Pearson'!H17 -> Kuat / Positif
A19: X3 - Total Man Power | B19: ='Korelasi Pearson'!B18 -> -0.41361305 | C19: ='Korelasi Pearson'!C18*100 -> 17.107576 | D19: ='Korelasi Pearson'!D18 -> -2.4038969 | E19: ='Korelasi Pearson'!F18 -> 0.023085683 | F19: ='Korelasi Pearson'!G18 -> Signifikan (Tolak H0) | G19: ='Korelasi Pearson'!H18 -> Sedang / Negatif
A21: C. HASIL UJI F (KELAYAKAN MODEL SIMULTAN)
A22: F-hitung | B22: =Regresi!E28 -> 8.6890148
A23: F-tabel (α=5%) | B23: =Regresi!F28 -> 2.975154
A24: P-Value (Sig. F) | B24: =Regresi!G28 -> 0.00036769477
A25: df (k ; n-k-1) | B25: =Regresi!C28&" ; "&Regresi!C29 -> 3 ; 26
A26: Keputusan | B26: =Regresi!H28 -> Model SIGNIFIKAN / layak digunakan
A27: =IF(Regresi!G28<0.05,"Kesimpulan: P-Value uji F < 0,05 sehingga H0 ditolak — Hari Kerja, Volume Produksi, dan Man Power secara bersama-sama berpengaruh signifikan terhadap Index Overtime.","Kesimpulan: P-Value uji F > 0,05 — secara simultan ketiga variabel belum terbukti berpengaruh signifikan terhadap Index Overtime.") -> Kesimpulan: P-Value uji F < 0,05 sehingga H0 ditolak — Hari Kerja, Volume Produksi, dan Man Power secara bersama-sama berpengaruh signifikan terhadap Index Overtime.
A29: D. HASIL REGRESI LINIER BERGANDA (UJI t & P-VALUE)
A30: Variabel | B30: Koefisien (Satuan Index) | C30: Std Error | D30: t-hitung | E30: P-Value | F30: Keputusan | G30: Arti Praktis
A31: Intercept (b0) | B31: =Regresi!B20 -> 114350.62 | C31: =Regresi!C20 -> 60994.023 | D31: =Regresi!D20 -> 1.874784 | E31: =Regresi!E20 -> 0.072098651 | F31: =Regresi!G20 -> Tidak Signifikan | G31: Konstanta model.
A32: X1 - Jumlah Hari Kerja | B32: =Regresi!B21 -> -1417.3264 | C32: =Regresi!C21 -> 1643.9125 | D32: =Regresi!D21 -> -0.86216659 | E32: =Regresi!E21 -> 0.39647851 | F32: =Regresi!G21 -> Tidak Signifikan | G32: Setiap tambahan 1 hari kerja mengubah Index Overtime sebesar nilai koefisien (ceteris paribus) turun 1.417 index.
A33: X2 - Volume Produksi | B33: =Regresi!B22 -> 28.43892 | C33: =Regresi!C22 -> 6.8897849 | D33: =Regresi!D22 -> 4.1276935 | E33: =Regresi!E22 -> 0.00033485833 | F33: =Regresi!G22 -> Signifikan | G33: Setiap tambahan 1 unit Volume Produksi mengubah Index Overtime sebesar 28 index
A34: X3 - Total Man Power | B34: =Regresi!B23 -> -131.50163 | C34: =Regresi!C23 -> 64.837729 | D34: =Regresi!D23 -> -2.0281653 | E34: =Regresi!E23 -> 0.052904187 | F34: =Regresi!G23 -> Tidak Signifikan | G34: Setiap tambahan 1 orang Man Power menurunkan Index Overtime sebesar 132 (nilai Koefisien)
A36: Persamaan Regresi | B36: =Regresi!A42 -> Y = 114350,61667 + (-1417,32644 x X1) + (28,43892 x X2) + (-131,50163 x X3)
A37: R (korelasi berganda) | B37: =Regresi!B34 -> 0.70756189
A38: R² (koefisien determinasi) | B38: =Regresi!B35 -> 0.50064383
A39: R² dalam % | B39: =Regresi!B36 -> 50.064383
A40: Adjusted R² | B40: =Regresi!B37 -> 0.44302581
A41: Standard Error of Estimate | B41: =Regresi!B38 -> 14901.697
A42: MAPE (rata-rata error prediksi, %) | B42: =Regresi!B39 -> 17.024696
A43: ="Artinya "&TEXT(Regresi!B36,"0.0")&"% variasi Index Overtime dapat dijelaskan oleh Hari Kerja, Volume Produksi, dan Man Power; sisanya "&TEXT(100-Regresi!B36,"0.0")&"% dijelaskan faktor lain di luar model (mis. breakdown mesin, absensi, urgensi pengiriman)." -> Artinya 50% variasi Index Overtime dapat dijelaskan oleh Hari Kerja, Volume Produksi, dan Man Power; sisanya 50% dijelaskan faktor lain di luar model (mis. breakdown mesin, absensi, urgensi pengiriman).
A45: E. INDEX IDEAL & POTENSI EFISIENSI
A46: Rata-rata Index Overtime aktual | B46: =AVERAGE('Index Ideal'!F3:F32) -> 68629.5
...

Sheet Data
A1: DATA TRAINING — Jan 2024 s.d Jun 2026 (Aktual)
A2: Year | B2: Month | C2: t | D2: Jumlah Hari Kerja (X1) | E2: Volume Produksi (X2) | F2: Total Man Power (X3) | G2: Total Index Overtime (Y) | I2: STATISTIK DESKRIPTIF
A3: 2024 | B3: Januari | C3: 1 | D3: 20 | E3: 3107 | F3: 845 | G3: 81305 | I3: Variabel | J3: N | K3: Mean | L3: Std Dev | M3: Min | N3: Max | O3: CV (%)
A4: 2024 | B4: Februari | C4: 2 | D4: 22 | E4: 2694 | F4: 814 | G4: 67057 | I4: Jumlah Hari Kerja (X1) | J4: =COUNT(D3:D32) -> 30 | K4: =AVERAGE(D3:D32) -> 20.066667 | L4: =STDEV(D3:D32) -> 1.7603552 | M4: =MIN(D3:D32) -> 16 | N4: =MAX(D3:D32) -> 23 | O4: =L4/K4*100 -> 8.7725344
A5: 2024 | B5: Maret | C5: 3 | D5: 19 | E5: 2211 | F5: 798 | G5: 39619 | I5: Volume Produksi (X2) | J5: =COUNT(E3:E32) -> 30 | K5: =AVERAGE(E3:E32) -> 2770.5667 | L5: =STDEV(E3:E32) -> 429.62026 | M5: =MIN(E3:E32) -> 1998 | N5: =MAX(E3:E32) -> 3698 | O5: =L5/K5*100 -> 15.506584
A6: 2024 | B6: April | C6: 4 | D6: 19 | E6: 2352 | F6: 789 | G6: 42895 | I6: Total Man Power (X3) | J6: =COUNT(F3:F32) -> 30 | K6: =AVERAGE(F3:F32) -> 740.56667 | L6: =STDEV(F3:F32) -> 43.703297 | M6: =MIN(F3:F32) -> 690 | N6: =MAX(F3:F32) -> 845 | O6: =L6/K6*100 -> 5.9013319
A7: 2024 | B7: Mei | C7: 5 | D7: 16 | E7: 2008 | F7: 756 | G7: 36966 | I7: Total Index Overtime (Y) | J7: =COUNT(G3:G32) -> 30 | K7: =AVERAGE(G3:G32) -> 67315.8 | L7: =STDEV(G3:G32) -> 19967.246 | M7: =MIN(G3:G32) -> 29413 | N7: =MAX(G3:G32) -> 100190 | O7: =L7/K7*100 -> 29.66205
A8: 2024 | B8: Juni | C8: 6 | D8: 20 | E8: 2659 | F8: 790 | G8: 59948
A9: 2024 | B9: Juli | C9: 7 | D9: 19 | E9: 2839 | F9: 790 | G9: 82171
A10: 2024 | B10: Agustus | C10: 8 | D10: 22 | E10: 3374 | F10: 690 | G10: 90534
A11: 2024 | B11: September | C11: 9 | D11: 22 | E11: 3208 | F11: 690 | G11: 100190 | I11: Variabel | J11: Mean | K11: Standar Deviasi | L11: Coefficient of Variation | M11: Interpretasi
A12: 2024 | B12: Oktober | C12: 10 | D12: 20 | E12: 3023 | F12: 697 | G12: 91437 | I12: Jumlah Hari Kerja (X1) | J12: 20 | K12: 1.8003831 | L12: 0.09 | M12: Variasi data Homogen memiliki fluktuasi rendah
A13: 2024 | B13: November | C13: 11 | D13: 23 | E13: 3237 | F13: 700 | G13: 76332 | I13: Volume Produksi (X2) | J13: 2725.3667 | K13: 390.95987 | L13: 0.1535 | M13: Variasi data Heterogen memiliki fluktuasi yang sedang
A14: 2024 | B14: December | C14: 12 | D14: 22 | E14: 3014 | F14: 699 | G14: 62074 | I14: Total Man Power (X3) | J14: 740.56667 | K14: 43.703297 | L14: 0.059 | M14: Variasi data Homogen memiliki fluktuasi rendah
A15: 2025 | B15: Januari | C15: 13 | D15: 18 | E15: 2617 | F15: 694 | G15: 89619 | I15: Total Index Overtime (Y) | J15: 67315.8 | K15: 19967.246 | L15: 0.3066 | M15: Variasi data Heterogen, memiliki fluktuasi tinggi
A16: 2025 | B16: Februari | C16: 14 | D16: 20 | E16: 2443 | F16: 706 | G16: 75216
A17: 2025 | B17: Maret | C17: 15 | D17: 20 | E17: 3004 | F17: 706 | G17: 78847
A18: 2025 | B18: April | C18: 16 | D18: 19 | E18: 2934 | F18: 707 | G18: 92254
A19: 2025 | B19: Mei | C19: 17 | D19: 17 | E19: 2717 | F19: 707 | G19: 68708
A20: 2025 | B20: Juni | C20: 18 | D20: 19 | E20: 2960 | F20: 708 | G20: 91078
A21: 2025 | B21: Juli | C21: 19 | D21: 19 | E21: 2832 | F21: 794 | G21: 73434
A22: 2025 | B22: Agustus | C22: 20 | D22: 23 | E22: 3402 | F22: 787 | G22: 60522
A23: 2025 | B23: September | C23: 21 | D23: 21 | E23: 2747 | F23: 775 | G23: 44904
A24: 2025 | B24: Oktober | C24: 22 | D24: 21 | E24: 2456 | F24: 775 | G24: 45540
A25: 2025 | B25: November | C25: 23 | D25: 22 | E25: 2463 | F25: 733 | G25: 38491
A26: 2025 | B26: December | C26: 24 | D26: 22 | E26: 1998 | F26: 729 | G26: 29413
A27: 2026 | B27: Januari | C27: 25 | D27: 20 | E27: 2485 | F27: 730 | G27: 62983
... A32: 2026 | B32: Juni | C32: 30 | D32: 20 | E32: 3698 | F32: 714 | G32: 84449
A34: Catatan: seluruh angka biru = data input aktual dari user (hardcode). Semua sheet lain menghitung dari sini lewat formula.

Sheet Korelasi Pearson
A1: ANALISIS KORELASI PEARSON — Matriks r, Uji t dan P-Value
A3: n (jumlah observasi) | C3: =COUNT(Data!G3:G32) -> 30
A4: df = n - 2 | C4: =C3-2 -> 28
A5: alpha | C5: 0.05
A7: 1. MATRIKS KORELASI (r)
A8: Variable | B8: X1 - Hari Kerja | C8: X2 - Volume Produksi | D8: X3 - Man Power | E8: Y - Index Overtime
A9: X1 - Hari Kerja | B9: =CORREL(Data!D$3:D$32,Data!D$3:D$32) -> 1 | C9: =CORREL(Data!D$3:D$32,Data!E$3:E$32) -> 0.29193851 | D9: =CORREL(Data!D$3:D$32,Data!F$3:F$32) -> -0.042640295 | E9: =CORREL(Data!D$3:D$32,Data!G$3:G$32) -> 0.065955224
A10: X2 - Volume Produksi | B10: =CORREL(Data!E$3:E$32,Data!D$3:D$32) -> 0.29193851 | C10: =CORREL(Data!E$3:E$32,Data!E$3:E$32) -> 1 | D10: =CORREL(Data!E$3:E$32,Data!F$3:F$32) -> -0.21427894 | E10: =CORREL(Data!E$3:E$32,Data!G$3:G$32) -> 0.6370945
A11: X3 - Man Power | B11: =CORREL(Data!F$3:F$32,Data!D$3:D$32) -> -0.042640295 | C11: =CORREL(Data!F$3:F$32,Data!E$3:E$32) -> -0.21427894 | D11: =CORREL(Data!F$3:F$32,Data!F$3:F$32) -> 1 | E11: =CORREL(Data!F$3:F$32,Data!G$3:G$32) -> -0.41361305
A12: Y - Index Overtime | B12: =CORREL(Data!G$3:G$32,Data!D$3:D$32) -> 0.065955224 | C12: =CORREL(Data!G$3:G$32,Data!E$3:E$32) -> 0.6370945 | D12: =CORREL(Data!G$3:G$32,Data!F$3:F$32) -> -0.41361305 | E12: =CORREL(Data!G$3:G$32,Data!G$3:G$32) -> 1
A14: 2. UJI SIGNIFIKANSI KORELASI TERHADAP Y (Index Overtime)
A15: Pasangan Variabel | B15: r (Pearson) | C15: r² (Koefisien Determinasi) | D15: t-hitung = r*AKAR(df)/AKAR(1-r²) | E15: t-tabel (2 sisi, 5%) | F15: P-Value | G15: Keputusan | H15: Kekuatan Hubungan
A16: X1 - Jumlah Hari Kerja vs Y | B16: =CORREL(Data!D3:D32,Data!G3:G32) -> 0.065955224 | C16: =B16^2 -> 0.0043500916 | D16: =B16*SQRT($C$4)/SQRT(1-B16^2) -> 0.34976382 | E16: =TINV($C$5,$C$4) -> 2.0484071 | F16: =TDIST(ABS(D16),$C$4,2) -> 0.72913314 | G16: =IF(F16<$C$5,"Signifikan (Tolak H0)","Tidak Signifikan (Terima H0)") -> Tidak Signifikan (Terima H0) | H16: =IF(ABS(B16)>=0.8,"Sangat Kuat",IF(ABS(B16)>=0.6,"Kuat",IF(ABS(B16)>=0.4,"Sedang",IF(ABS(B16)>=0.2,"Lemah","Sangat Lemah"))))&IF(B16>0," / Positif"," / Negatif") -> Sangat Lemah / Positif
A17: X2 - Volume Produksi vs Y | B17: =CORREL(Data!E3:E32,Data!G3:G32) -> 0.6370945 | C17: =B17^2 -> 0.40588941 | D17: =B17*SQRT($C$4)/SQRT(1-B17^2) -> 4.3737024 | E17: =TINV($C$5,$C$4) -> 2.0484071 | F17: =TDIST(ABS(D17),$C$4,2) -> 0.00015319005 | G17: =IF(F17<$C$5,"Signifikan (Tolak H0)","Tidak Signifikan (Terima H0)") -> Signifikan (Tolak H0) | H17: =IF(ABS(B17)>=0.8,"Sangat Kuat",IF(ABS(B17)>=0.6,"Kuat",IF(ABS(B17)>=0.4,"Sedang",IF(ABS(B17)>=0.2,"Lemah","Sangat Lemah"))))&IF(B17>0," / Positif"," / Negatif") -> Kuat / Positif
A18: X3 - Total Man Power vs Y | B18: =CORREL(Data!F3:F32,Data!G3:G32) -> -0.41361305 | C18: =B18^2 -> 0.17107576 | D18: =B18*SQRT($C$4)/SQRT(1-B18^2) -> -2.4038969 | E18: =TINV($C$5,$C$4) -> 2.0484071 | F18: =TDIST(ABS(D18),$C$4,2) -> 0.023085683 | G18: =IF(F18<$C$5,"Signifikan (Tolak H0)","Tidak Signifikan (Terima H0)") -> Signifikan (Tolak H0) | H18: =IF(ABS(B18)>=0.8,"Sangat Kuat",IF(ABS(B18)>=0.6,"Kuat",IF(ABS(B18)>=0.4,"Sedang",IF(ABS(B18)>=0.2,"Lemah","Sangat Lemah"))))&IF(B18>0," / Positif"," / Negatif") -> Sedang / Negatif
A20: H0: r = 0 (tidak ada hubungan linier) | H1: r ≠ 0 (ada hubungan linier). Tolak H0 bila P-Value < alpha (0,05).
A22: 3. CEK MULTIKOLINEARITAS ANTAR PREDIKTOR
A23: Pasangan | B23: r | C23: P-Value | D23: Catatan
A24: X1 vs X2 | B24: =CORREL(Data!D3:D32,Data!E3:E32) -> 0.29193851 | C24: =TDIST(ABS(B24*SQRT($C$4)/SQRT(1-B24^2)),$C$4,2) -> 0.11749121 | D24: =IF(ABS(B24)>0.8,"Indikasi multikolinearitas kuat","Aman (r<0,8)") -> Aman (r<0,8)
A25: X1 vs X3 | B25: =CORREL(Data!D3:D32,Data!F3:F32) -> -0.042640295 | C25: =TDIST(ABS(B25*SQRT($C$4)/SQRT(1-B25^2)),$C$4,2) -> 0.82296887 | D25: =IF(ABS(B25)>0.8,"Indikasi multikolinearitas kuat","Aman (r<0,8)") -> Aman (r<0,8)
A26: X2 vs X3 | B26: =CORREL(Data!E3:E32,Data!F3:F32) -> -0.21427894 | C26: =TDIST(ABS(B26*SQRT($C$4)/SQRT(1-B26^2)),$C$4,2) -> 0.25551641 | D26: =IF(ABS(B26)>0.8,"Indikasi multikolinearitas kuat","Aman (r<0,8)") -> Aman (r<0,8)

Sheet Regresi
A1: ANALISIS REGRESI LINIER BERGANDA (Y = b0 + b1·X1 + b2·X2 + b3·X3)
A2: Y = Total Index Overtime | X1 = Jumlah Hari Kerja | X2 = Volume Produksi | X3 = Total Man Power
A4: n | B4: =COUNT(Data!G3:G32) -> 30
A5: k (jumlah prediktor) | B5: 3
A6: df regresi = k | B6: =B5 -> 3
A7: df residual = n-k-1 | B7: =B4-B5-1 -> 26
A8: alpha | B8: 0.05
A10: 1. OUTPUT LINEST (array di-unpack dengan INDEX agar semua sel ter-link)
A11: Matrix | B11: m3 (X3 Man Power) | C11: m2 (X2 Volume) | D11: m1 (X1 Hari Kerja) | E11: b (Intercept)
A12: Koefisien | B12: =INDEX(LINEST(Data!$G$3:$G$32,Data!$D$3:$F$32,TRUE(),TRUE()),1,1) -> -131.50163 | C12: =INDEX(LINEST(Data!$G$3:$G$32,Data!$D$3:$F$32,TRUE(),TRUE()),1,2) -> 28.43892 | D12: =INDEX(LINEST(Data!$G$3:$G$32,Data!$D$3:$F$32,TRUE(),TRUE()),1,3) -> -1417.3264 | E12: =INDEX(LINEST(Data!$G$3:$G$32,Data!$D$3:$F$32,TRUE(),TRUE()),1,4) -> 114350.62
A13: Std Error | B13: =INDEX(LINEST(Data!$G$3:$G$32,Data!$D$3:$F$32,TRUE(),TRUE()),2,1) -> 64.837729 | C13: =INDEX(LINEST(Data!$G$3:$G$32,Data!$D$3:$F$32,TRUE(),TRUE()),2,2) -> 6.8897849 | D13: =INDEX(LINEST(Data!$G$3:$G$32,Data!$D$3:$F$32,TRUE(),TRUE()),2,3) -> 1643.9125 | E13: =INDEX(LINEST(Data!$G$3:$G$32,Data!$D$3:$F$32,TRUE(),TRUE()),2,4) -> 60994.023
A14: R² / SE(Y) | B14: =INDEX(LINEST(Data!$G$3:$G$32,Data!$D$3:$F$32,TRUE(),TRUE()),3,1) -> 0.50064383 | C14: =INDEX(LINEST(Data!$G$3:$G$32,Data!$D$3:$F$32,TRUE(),TRUE()),3,2) -> 14901.697 | D14: =IFERROR(INDEX(LINEST(Data!$G$3:$G$32,Data!$D$3:$F$32,TRUE(),TRUE()),3,3),"-") -> - | E14: =IFERROR(INDEX(LINEST(Data!$G$3:$G$32,Data!$D$3:$F$32,TRUE(),TRUE()),3,4),"-") -> -
A15: F / df residual | B15: =INDEX(LINEST(Data!$G$3:$G$32,Data!$D$3:$F$32,TRUE(),TRUE()),4,1) -> 8.6890148 | C15: =INDEX(LINEST(Data!$G$3:$G$32,Data!$D$3:$F$32,TRUE(),TRUE()),4,2) -> 26 | D15: =IFERROR(INDEX(LINEST(Data!$G$3:$G$32,Data!$D$3:$F$32,TRUE(),TRUE()),4,3),"-") -> - | E15: =IFERROR(INDEX(LINEST(Data!$G$3:$G$32,Data!$D$3:$F$32,TRUE(),TRUE()),4,4),"-") -> -
A16: SS Regresi / SS Residual | B16: =INDEX(LINEST(Data!$G$3:$G$32,Data!$D$3:$F$32,TRUE(),TRUE()),5,1) -> 5.7884625e+09 | C16: =INDEX(LINEST(Data!$G$3:$G$32,Data!$D$3:$F$32,TRUE(),TRUE()),5,2) -> 5.7735746e+09 | D16: =IFERROR(INDEX(LINEST(Data!$G$3:$G$32,Data!$D$3:$F$32,TRUE(),TRUE()),5,3),"-") -> - | E16: =IFERROR(INDEX(LINEST(Data!$G$3:$G$32,Data!$D$3:$F$32,TRUE(),TRUE()),5,4),"-") -> -
A18: 2. TABEL KOEFISIEN, UJI t DAN P-VALUE
A19: Variabel | B19: Koefisien | C19: Std Error | D19: t-hitung | E19: P-Value | F19: t-tabel | G19: Keputusan (α=5%) | H19: Batas Bawah 95% | I19: Batas Atas 95%
A20: Intercept (b0) | B20: =E12 -> 114350.62 | C20: =E13 -> 60994.023 | D20: =B20/C20 -> 1.874784 | E20: =TDIST(ABS(D20),$B$7,2) -> 0.072098651 | F20: =TINV($B$8,$B$7) -> 2.0555294 | G20: =IF(E20<$B$8,"Signifikan","Tidak Signifikan") -> Tidak Signifikan | H20: =B20-F20*C20 -> -11024.392 | I20: =B20+F20*C20 -> 239725.63
A21: X1 - Jumlah Hari Kerja (b1) | B21: =D12 -> -1417.3264 | C21: =D13 -> 1643.9125 | D21: =B21/C21 -> -0.86216659 | E21: =TDIST(ABS(D21),$B$7,2) -> 0.39647851 | F21: =TINV($B$8,$B$7) -> 2.0555294 | G21: =IF(E21<$B$8,"Signifikan","Tidak Signifikan") -> Tidak Signifikan | H21: =B21-F21*C21 -> -4796.437 | I21: =B21+F21*C21 -> 1961.7841
A22: X2 - Volume Produksi (b2) | B22: =C12 -> 28.43892 | C22: =C13 -> 6.8897849 | D22: =B22/C22 -> 4.1276935 | E22: =TDIST(ABS(D22),$B$7,2) -> 0.00033485833 | F22: =TINV($B$8,$B$7) -> 2.0555294 | G22: =IF(E22<$B$8,"Signifikan","Tidak Signifikan") -> Signifikan | H22: =B22-F22*C22 -> 14.276764 | I22: =B22+F22*C22 -> 42.601076
A23: X3 - Total Man Power (b3) | B23: =B12 -> -131.50163 | C23: =B13 -> 64.837729 | D23: =B23/C23 -> -2.0281653 | E23: =TDIST(ABS(D23),$B$7,2) -> 0.052904187 | F23: =TINV($B$8,$B$7) -> 2.0555294 | G23: =IF(E23<$B$8,"Signifikan","Tidak Signifikan") -> Tidak Signifikan | H23: =B23-F23*C23 -> -264.77749 | I23: =B23+F23*C23 -> 1.7742314
A24: Uji t: H0: bi = 0 (variabel tidak berpengaruh) | H1: bi ≠ 0. Tolak H0 bila P-Value < 0,05.
A26: 3. UJI F (ANOVA) — Kelayakan Model Secara Simultan
A27: Sumber Variasi | B27: SS (Sum of Squares) | C27: df | D27: MS (Mean Square) | E27: F-hitung | F27: F-tabel | G27: P-Value (Sig. F) | H27: Keputusan
A28: Regresi | B28: =B16 -> 5.7884625e+09 | C28: =B6 -> 3 | D28: =B28/C28 -> 1.9294875e+09 | E28: =D28/D29 -> 8.6890148 | F28: =FINV($B$8,$B$6,$B$7) -> 2.975154 | G28: =FDIST(E28,$B$6,$B$7) -> 0.00036769477 | H28: =IF(G28<$B$8,"Model SIGNIFIKAN / layak digunakan","Model tidak signifikan") -> Model SIGNIFIKAN / layak digunakan
A29: Residual | B29: =C16 -> 5.7735746e+09 | C29: =B7 -> 26 | D29: =B29/C29 -> 2.2206056e+08
A30: Total | B30: =B28+B29 -> 1.1562037e+10 | C30: =C28+C29 -> 29
A31: Uji F: H0: b1=b2=b3=0 | H1: minimal satu bi ≠ 0. Tolak H0 bila Sig. F < 0,05.
A33: 4. GOODNESS OF FIT
A34: R (koefisien korelasi berganda) | B34: =SQRT(B14) -> 0.70756189
A35: R² (koefisien determinasi) | B35: =B14 -> 0.50064383
A36: R² dalam % | B36: =B14*100 -> 50.064383
A37: Adjusted R² | B37: =1-((1-B14)*(B4-1)/(B4-B5-1)) -> 0.44302581
A38: Standard Error of Estimate | B38: =C14 -> 14901.697
A39: MAPE model (%) | B39: =AVERAGE('Index Ideal'!J3:J32) -> 17.024696
A41: 5. PERSAMAAN REGRESI TERBENTUK
A42: ="Y = "&TEXT(B20,"#,##0.00")&" + ("&TEXT(B21,"#,##0.00")&" x X1) + ("&TEXT(B22,"#,##0.00")&" x X2) + ("&TEXT(B23,"#,##0.00")&" x X3)" -> Y = 114350,61667 + (-1417,32644 x X1) + (28,43892 x X2) + (-131,50163 x X3)

Sheet Uji Asumsi Klasik
A1: UJI ASUMSI KLASIK — Normalitas, Autokorelasi, Heteroskedastisitas, Multikolinearitas
A2: Semua perhitungan memakai residual dari model regresi pada sheet Regresi
K3: Kolom bantu untuk perhitungan VIF
A4: t | B4: Periode | C4: Y Aktual | D4: Y Prediksi (Fitted) | E4: Residual (e) | F4: e² | G4: |e| | H4: Residual Baku | I4: (e(t)-e(t-1))² | K4: X1 | L4: X2 | M4: X3 | N4: X2 | O4: X1 | P4: X3
A5: =Data!C3 -> 1 | B5: =Data!B3&" "&Data!A3 -> Januari 2024 | C5: =Data!G3 -> 81305 | D5: ='Index Ideal'!G3 -> 63244.936 | E5: =C5-D5 -> 18060.064 | F5: =E5^2 -> 3.2616593e+08 | G5: =ABS(E5) -> 18060.064 | H5: =E5/Regresi!$B$38 -> 1.2119469 | I5: - | K5: =Data!D3 -> 20 | L5: =Data!E3 -> 3107 | M5: =Data!F3 -> 845 | N5: =Data!E3 -> 3107 | O5: =Data!D3 -> 20 | P5: =Data!F3 -> 845
A6: =Data!C4 -> 2 | B6: =Data!B4&" "&Data!A4 -> Februari 2024 | C6: =Data!G4 -> 67057 | D6: ='Index Ideal'!G4 -> 52741.559 | E6: =C6-D6 -> 14315.441 | F6: =E6^2 -> 2.0493185e+08 | G6: =ABS(E6) -> 14315.441 | H6: =E6/Regresi!$B$38 -> 0.96065846 | I6: =(E6-E5)^2 -> 14022206 | K6: =Data!D4 -> 22 | L6: =Data!E4 -> 2694 | M6: =Data!F4 -> 814 | N6: =Data!E4 -> 2694 | O6: =Data!D4 -> 22 | P6: =Data!F4 -> 814
A7: =Data!C5 -> 3 | B7: =Data!B5&" "&Data!A5 -> Maret 2024 | C7: =Data!G5 -> 39619 | D7: ='Index Ideal'!G5 -> 45361.566 | E7: =C7-D7 -> -5742.5661 | F7: =E7^2 -> 32977066 | G7: =ABS(E7) -> 5742.5661 | H7: =E7/Regresi!$B$38 -> -0.38536324 | I7: =(E7-E6)^2 -> 4.0232364e+08 | K7: =Data!D5 -> 19 | L7: =Data!E5 -> 2211 | M7: =Data!F5 -> 798 | N7: =Data!E5 -> 2211 | O7: =Data!D5 -> 19 | P7: =Data!F5 -> 798
A8: =Data!C6 -> 4 | B8: =Data!B6&" "&Data!A6 -> April 2024 | C8: =Data!G6 -> 42895 | D8: ='Index Ideal'!G6 -> 50554.969 | E8: =C8-D8 -> -7659.9686 | F8: =E8^2 -> 58675118 | G8: =ABS(E8) -> 7659.9686 | H8: =E8/Regresi!$B$38 -> -0.51403332 | I8: =(E8-E7)^2 -> 3676432 | K8: =Data!D6 -> 19 | L8: =Data!E6 -> 2352 | M8: =Data!F6 -> 789 | N8: =Data!E6 -> 2352 | O8: =Data!D6 -> 19 | P8: =Data!F6 -> 789
A9: =Data!C7 -> 5 | B9: =Data!B7&" "&Data!A7 -> Mei 2024 | C9: =Data!G7 -> 36966 | D9: ='Index Ideal'!G7 -> 49363.513 | E9: =C9-D9 -> -12397.513 | F9: =E9^2 -> 1.5369833e+08 | G9: =ABS(E9) -> 12397.513 | H9: =E9/Regresi!$B$38 -> -0.83195313 | I9: =(E9-E8)^2 -> 22444328 | K9: =Data!D7 -> 16 | L9: =Data!E7 -> 2008 | M9: =Data!F7 -> 756 | N9: =Data!E7 -> 2008 | O9: =Data!D7 -> 16 | P9: =Data!F7 -> 756
A10: =Data!C8 -> 6 | B10: =Data!B8&" "&Data!A8 -> Juni 2024 | C10: =Data!G8 -> 59948 | D10: ='Index Ideal'!G8 -> 57736.889 | E10: =C10-D10 -> 2211.111 | F10: =E10^2 -> 4889011.9 | G10: =ABS(E10) -> 2211.111 | H10: =E10/Regresi!$B$38 -> 0.14837982 | I10: =(E10-E9)^2 -> 2.134119e+08 | K10: =Data!D8 -> 20 | L10: =Data!E8 -> 2659 | M10: =Data!F8 -> 790 | N10: =Data!E8 -> 2659 | O10: =Data!D8 -> 20 | P10: =Data!F8 -> 790
A11: =Data!C9 -> 7 | B11: =Data!B9&" "&Data!A9 -> Juli 2024 | C11: =Data!G9 -> 82171 | D11: ='Index Ideal'!G9 -> 64273.221 | E11: =C11-D11 -> 17897.779 | F11: =E11^2 -> 3.2033049e+08 | G11: =ABS(E11) -> 17897.779 | H11: =E11/Regresi!$B$38 -> 1.2010565 | I11: =(E11-E10)^2 -> 2.4607155e+08 | K11: =Data!D9 -> 19 | L11: =Data!E9 -> 2839 | M11: =Data!F9 -> 790 | N11: =Data!E9 -> 2839 | O11: =Data!D9 -> 19 | P11: =Data!F9 -> 790
A12: =Data!C10 -> 8 | B12: =Data!B10&" "&Data!A10 -> Agustus 2024 | C12: =Data!G10 -> 90534 | D12: ='Index Ideal'!G10 -> 88386.227 | E12: =C12-D12 -> 2147.7729 | F12: =E12^2 -> 4612928.6 | G12: =ABS(E12) -> 2147.7729 | H12: =E12/Regresi!$B$38 -> 0.14412942 | I12: =(E12-E11)^2 -> 2.4806269e+08 | K12: =Data!D10 -> 22 | L12: =Data!E10 -> 3374 | M12: =Data!F10 -> 690 | N12: =Data!E10 -> 3374 | O12: =Data!D10 -> 22 | P12: =Data!F10 -> 690
A13: =Data!C11 -> 9 | B13: =Data!B11&" "&Data!A11 -> September 2024 | C13: =Data!G11 -> 100190 | D13: ='Index Ideal'!G11 -> 83665.366 | E13: =C13-D13 -> 16524.634 | F13: =E13^2 -> 2.7306352e+08 | G13: =ABS(E13) -> 16524.634 | H13: =E13/Regresi!$B$38 -> 1.1089096 | I13: =(E13-E12)^2 -> 2.0669413e+08 | K13: =Data!D11 -> 22 | L13: =Data!E11 -> 3208 | M13: =Data!F11 -> 690 | N13: =Data!E11 -> 3208 | O13: =Data!D11 -> 22 | P13: =Data!F11 -> 690
A14: =Data!C12 -> 10 | B14: =Data!B12&" "&Data!A12 -> Oktober 2024 | C14: =Data!G12 -> 91437 | D14: ='Index Ideal'!G12 -> 80318.308 | E14: =C14-D14 -> 11118.692 | F14: =E14^2 -> 1.2362532e+08 | G14: =ABS(E14) -> 11118.692 | H14: =E14/Regresi!$B$38 -> 0.74613601 | I14: =(E14-E13)^2 -> 29224201 | K14: =Data!D12 -> 20 | L14: =Data!E12 -> 3023 | M14: =Data!F12 -> 697 | N14: =Data!E12 -> 3023 | O14: =Data!D12 -> 20 | P14: =Data!F12 -> 697
A15: =Data!C13 -> 11 | B15: =Data!B13&" "&Data!A13 -> November 2024 | C15: =Data!G13 -> 76332 | D15: ='Index Ideal'!G13 -> 81757.752 | E15: =C15-D15 -> -5425.7522 | F15: =E15^2 -> 29438787 | G15: =ABS(E15) -> 5425.7522 | H15: =E15/Regresi!$B$38 -> -0.36410299 | I15: =(E15-E14)^2 -> 2.7371865e+08 | K15: =Data!D13 -> 23 | L15: =Data!E13 -> 3237 | M15: =Data!F13 -> 700 | N15: =Data!E13 -> 3237 | O15: =Data!D13 -> 23 | P15: =Data!F13 -> 700
A16: =Data!C14 -> 12 | B16: =Data!B14&" "&Data!A14 -> December 2024 | C16: =Data!G14 -> 62074 | D16: ='Index Ideal'!G14 -> 76964.701 | E16: =C16-D16 -> -14890.701 | F16: =E16^2 -> 2.2173298e+08 | G16: =ABS(E16) -> 14890.701 | H16: =E16/Regresi!$B$38 -> -0.99926213 | I16: =(E16-E15)^2 -> 89585257 | K16: =Data!D14 -> 22 | L16: =Data!E14 -> 3014 | M16: =Data!F14 -> 699 | N16: =Data!E14 -> 3014 | O16: =Data!D14 -> 22 | P16: =Data!F14 -> 699
A17: =Data!C15 -> 13 | B17: =Data!B15&" "&Data!A15 -> Januari 2025 | C17: =Data!G15 -> 89619 | D17: ='Index Ideal'!G15 -> 72001.264 | E17: =C17-D17 -> 17617.736 | F17: =E17^2 -> 3.1038463e+08 | G17: =ABS(E17) -> 17617.736 | H17: =E17/Regresi!$B$38 -> 1.1822638 | I17: =(E17-E16)^2 -> 1.0567985e+09 | K17: =Data!D15 -> 18 | L17: =Data!E15 -> 2617 | M17: =Data!F15 -> 694 | N17: =Data!E15 -> 2617 | O17: =Data!D15 -> 18 | P17: =Data!F15 -> 694
... A34: =Data!C32 -> 30 | B34: =Data!B32&" "&Data!A32 -> Juni 2026 | C34: =Data!G32 -> 84449 | D34: ='Index Ideal'!G32 -> 97279.051 | E34: =C34-D34 -> -12830.051 | F34: =E34^2 -> 1.6461021e+08 | G34: =ABS(E34) -> 12830.051 | H34: =E34/Regresi!$B$38 -> -0.86097921 | I34: =(E34-E33)^2 -> 7.1093672e+08 | K34: =Data!D32 -> 20 | L34: =Data!E32 -> 3698 | M34: =Data!F32 -> 714 | N34: =Data!E32 -> 3698 | O34: =Data!D32 -> 20 | P34: =Data!F32 -> 714
A35: Jumlah | E35: =SUM(E5:E34) -> -5.3842086e-10 | F35: =SUM(F5:F34) -> 5.7735746e+09 | I35: =SUM(I6:I34) -> 1.1063166e+10
A37: Skewness (kemencengan) | B37: =SKEW(E5:E34) -> -0.63120471
A38: Excess Kurtosis | B38: =KURT(E5:E34) -> 0.22181508
A39: n | B39: =COUNT(E5:E34) -> 30
A40: Jarque-Bera = n/6 x (S² + K²/4) | B40: =B39/6*(B37^2+B38^2/4) -> 2.0535994
A41: Chi-Square tabel (df=2; α=5%) | B41: =CHIINV(0.05,2) -> 5.9914645
A42: P-Value | B42: =CHIDIST(B40,2) -> 0.35815132
A43: Keputusan | B43: =IF(B42>0.05,"Residual BERDISTRIBUSI NORMAL (asumsi terpenuhi)","Residual tidak normal (asumsi tidak terpenuhi)") -> Residual BERDISTRIBUSI NORMAL (asumsi terpenuhi)
A44: Rata-rata residual (harus ≈ 0) | B44: =AVERAGE(E5:E34) -> -1.7947362e-11
A45: H0: residual berdistribusi normal. P-Value > 0,05 → H0 diterima → asumsi normalitas terpenuhi.
A47: 2. UJI AUTOKORELASI (Durbin-Watson) — penting karena data time series bulanan
A48: Σ (e(t) - e(t-1))² | B48: =I35 -> 1.1063166e+10
A49: Σ e² | B49: =F35 -> 5.7735746e+09
A50: Durbin-Watson (DW) | B50: =B48/B49 -> 1.9161726 | C50: Nilai dL & dU dari tabel Durbin-Watson (n=30; k=3). Sel kuning boleh diubah bila jumlah data/prediktor berubah. Asumsi aman bila dU < DW < 4-dU.
A51: dL (n=30; k=3; α=5%) | B51: 1.2138
A52: dU (n=30; k=3; α=5%) | B52: 1.6498
A53: 4 - dU | B53: =4-B52 -> 2.3502
A54: 4 - dL | B54: =4-B51 -> 2.7862
A55: Keputusan | B55: =IF(B50<B51,"Ada autokorelasi POSITIF",IF(B50<B52,"Daerah ragu-ragu (inconclusive)",IF(B50<=B53,"TIDAK ADA AUTOKORELASI (asumsi terpenuhi)",IF(B50<=B54,"Daerah ragu-ragu (inconclusive)","Ada autokorelasi NEGATIF")))) -> TIDAK ADA AUTOKORELASI (asumsi terpenuhi)
A56: Autokorelasi lag-1 residual (r) | B56: =CORREL(E5:E33,E6:E34) -> 0.00083233874
A57: 3. UJI HETEROSKEDASTISITAS (Glejser: |e| diregresi pada X1, X2, X3)
A58: Variabel | B58: Koefisien | C58: Std Error | D58: t-hitung | E58: P-Value | F58: Keputusan
...

Sheet Index Ideal
A1: INDEX OVERTIME IDEAL — Hasil Prediksi Model & Benchmark Efisiensi
A2: t | B2: Periode | C2: Hari Kerja | D2: Volume | E2: Man Power | F2: Overtime Aktual (Y) | G2: Index Ideal (Model Regresi) | H2: Selisih (Aktual - Ideal) | I2: % Deviasi | J2: APE (%) | K2: OT / Man Power | L2: OT / Volume | M2: Index Ideal Benchmark (Efisien) | N2: Potensi Penghematan | O2: Status
A3: =Data!C3 -> 1 | B3: =Data!B3&" "&Data!A3 -> Januari 2024 | C3: =Data!D3 -> 20 | D3: =Data!E3 -> 3107 | E3: =Data!F3 -> 845 | F3: =Data!G3 -> 81305 | G3: =Regresi!$B$20+Regresi!$B$21*C3+Regresi!$B$22*D3+Regresi!$B$23*E3 -> 63244.936 | H3: =F3-G3 -> 18060.064 | I3: =IF(G3=0,0,H3/G3*100) -> 28.555748 | J3: =IF(F3=0,0,ABS(H3)/F3*100) -> 22.212735 | K3: =F3/E3 -> 96.218935 | L3: =F3/D3 -> 26.16833 | M3: =$C$36*D3 -> 59205.639 | N3: =MAX(0,F3-M3) -> 22099.361 | O3: =IF(H3>0,"Over (di atas ideal)",IF(H3<0,"Under (di bawah ideal)","Tepat")) -> Over (di atas ideal)
A4: =Data!C4 -> 2 | B4: =Data!B4&" "&Data!A4 -> Februari 2024 | C4: =Data!D4 -> 22 | D4: =Data!E4 -> 2694 | E4: =Data!F4 -> 814 | F4: =Data!G4 -> 67057 | G4: =Regresi!$B$20+Regresi!$B$21*C4+Regresi!$B$22*D4+Regresi!$B$23*E4 -> 52741.559 | H4: =F4-G4 -> 14315.441 | I4: =IF(G4=0,0,H4/G4*100) -> 27.14262 | J4: =IF(F4=0,0,ABS(H4)/F4*100) -> 21.348168 | K4: =F4/E4 -> 82.379607 | L4: =F4/D4 -> 24.89124 | M4: =$C$36*D4 -> 51335.691 | N4: =MAX(0,F4-M4) -> 15721.309 | O4: =IF(H4>0,"Over (di atas ideal)",IF(H4<0,"Under (di bawah ideal)","Tepat")) -> Over (di atas ideal)
A5: =Data!C5 -> 3 | B5: =Data!B5&" "&Data!A5 -> Maret 2024 | C5: =Data!D5 -> 19 | D5: =Data!E5 -> 2211 | E5: =Data!F5 -> 798 | F5: =Data!G5 -> 39619 | G5: =Regresi!$B$20+Regresi!$B$21*C5+Regresi!$B$22*D5+Regresi!$B$23*E5 -> 45361.566 | H5: =F5-G5 -> -5742.5661 | I5: =IF(G5=0,0,H5/G5*100) -> -12.659541 | J5: =IF(F5=0,0,ABS(H5)/F5*100) -> 14.494475 | K5: =F5/E5 -> 49.64787 | L5: =F5/D5 -> 17.919041 | M5: =$C$36*D5 -> 42131.853 | N5: =MAX(0,F5-M5) -> 0 | O5: =IF(H5>0,"Over (di atas ideal)",IF(H5<0,"Under (di bawah ideal)","Tepat")) -> Under (di bawah ideal)
A6: =Data!C6 -> 4 | B6: =Data!B6&" "&Data!A6 -> April 2024 | C6: =Data!D6 -> 19 | D6: =Data!E6 -> 2352 | E6: =Data!F6 -> 789 | F6: =Data!G6 -> 42895 | G6: =Regresi!$B$20+Regresi!$B$21*C6+Regresi!$B$22*D6+Regresi!$B$23*E6 -> 50554.969 | H6: =F6-G6 -> -7659.9686 | I6: =IF(G6=0,0,H6/G6*100) -> -15.151762 | J6: =IF(F6=0,0,ABS(H6)/F6*100) -> 17.857486 | K6: =F6/E6 -> 54.366286 | L6: =F6/D6 -> 18.23767 | M6: =$C$36*D6 -> 44818.688 | N6: =MAX(0,F6-M6) -> 0 | O6: =IF(H6>0,"Over (di atas ideal)",IF(H6<0,"Under (di bawah ideal)","Tepat")) -> Under (di bawah ideal)
A7: =Data!C7 -> 5 | B7: =Data!B7&" "&Data!A7 -> Mei 2024 | C7: =Data!D7 -> 16 | D7: =Data!E7 -> 2008 | E7: =Data!F7 -> 756 | F7: =Data!G7 -> 36966 | G7: =Regresi!$B$20+Regresi!$B$21*C7+Regresi!$B$22*D7+Regresi!$B$23*E7 -> 49363.513 | H7: =F7-G7 -> -12397.513 | I7: =IF(G7=0,0,H7/G7*100) -> -25.11473 | J7: =IF(F7=0,0,ABS(H7)/F7*100) -> 33.537611 | K7: =F7/E7 -> 48.896825 | L7: =F7/D7 -> 18.409363 | M7: =$C$36*D7 -> 38263.574 | N7: =MAX(0,F7-M7) -> 0 | O7: =IF(H7>0,"Over (di atas ideal)",IF(H7<0,"Under (di bawah ideal)","Tepat")) -> Under (di bawah ideal)
A8: =Data!C8 -> 6 | B8: =Data!B8&" "&Data!A8 -> Juni 2024 | C8: =Data!D8 -> 20 | D8: =Data!E8 -> 2659 | E8: =Data!F8 -> 790 | F8: =Data!G8 -> 59948 | G8: =Regresi!$B$20+Regresi!$B$21*C8+Regresi!$B$22*D8+Regresi!$B$23*E8 -> 57736.889 | H8: =F8-G8 -> 2211.111 | I8: =IF(G8=0,0,H8/G8*100) -> 3.8296331 | J8: =IF(F8=0,0,ABS(H8)/F8*100) -> 3.6883816 | K8: =F8/E8 -> 75.883544 | L8: =F8/D8 -> 22.545318 | M8: =$C$36*D8 -> 50668.746 | N8: =MAX(0,F8-M8) -> 9279.2539 | O8: =IF(H8>0,"Over (di atas ideal)",IF(H8<0,"Under (di bawah ideal)","Tepat")) -> Over (di atas ideal)
A9: =Data!C9 -> 7 | B9: =Data!B9&" "&Data!A9 -> Juli 2024 | C9: =Data!D9 -> 19 | D9: =Data!E9 -> 2839 | E9: =Data!F9 -> 790 | F9: =Data!G9 -> 82171 | G9: =Regresi!$B$20+Regresi!$B$21*C9+Regresi!$B$22*D9+Regresi!$B$23*E9 -> 64273.221 | H9: =F9-G9 -> 17897.779 | I9: =IF(G9=0,0,H9/G9*100) -> 27.846401 | J9: =IF(F9=0,0,ABS(H9)/F9*100) -> 21.781138 | K9: =F9/E9 -> 104.01392 | L9: =F9/D9 -> 28.943642 | M9: =$C$36*D9 -> 54098.748 | N9: =MAX(0,F9-M9) -> 28072.252 | O9: =IF(H9>0,"Over (di atas ideal)",IF(H9<0,"Under (di bawah ideal)","Tepat")) -> Over (di atas ideal)
A10: =Data!C10 -> 8 | B10: =Data!B10&" "&Data!A10 -> Agustus 2024 | C10: =Data!D10 -> 22 | D10: =Data!E10 -> 3374 | E10: =Data!F10 -> 690 | F10: =Data!G10 -> 90534 | G10: =Regresi!$B$20+Regresi!$B$21*C10+Regresi!$B$22*D10+Regresi!$B$23*E10 -> 88386.227 | H10: =F10-G10 -> 2147.7729 | I10: =IF(G10=0,0,H10/G10*100) -> 2.429986 | J10: =IF(F10=0,0,ABS(H10)/F10*100) -> 2.3723385 | K10: =F10/E10 -> 131.2087 | L10: =F10/D10 -> 26.832839 | M10: =$C$36*D10 -> 64293.475 | N10: =MAX(0,F10-M10) -> 26240.525 | O10: =IF(H10>0,"Over (di atas ideal)",IF(H10<0,"Under (di bawah ideal)","Tepat")) -> Over (di atas ideal)
A11: =Data!C11 -> 9 | B11: =Data!B11&" "&Data!A11 -> September 2024 | C11: =Data!D11 -> 22 | D11: =Data!E11 -> 3208 | E11: =Data!F11 -> 690 | F11: =Data!G11 -> 100190 | G11: =Regresi!$B$20+Regresi!$B$21*C11+Regresi!$B$22*D11+Regresi!$B$23*E11 -> 83665.366 | H11: =F11-G11 -> 16524.634 | I11: =IF(G11=0,0,H11/G11*100) -> 19.750865 | J11: =IF(F11=0,0,ABS(H11)/F11*100) -> 16.493296 | K11: =F11/E11 -> 145.2029 | L11: =F11/D11 -> 31.231297 | M11: =$C$36*D11 -> 61130.251 | N11: =MAX(0,F11-M11) -> 39059.749 | O11: =IF(H11>0,"Over (di atas ideal)",IF(H11<0,"Under (di bawah ideal)","Tepat")) -> Over (di atas ideal)
A12: =Data!C12 -> 10 | B12: =Data!B12&" "&Data!A12 -> Oktober 2024 | C12: =Data!D12 -> 20 | D12: =Data!E12 -> 3023 | E12: =Data!F12 -> 697 | F12: =Data!G12 -> 91437 | G12: =Regresi!$B$20+Regresi!$B$21*C12+Regresi!$B$22*D12+Regresi!$B$23*E12 -> 80318.308 | H12: =F12-G12 -> 11118.692 | I12: =IF(G12=0,0,H12/G12*100) -> 13.843285 | J12: =IF(F12=0,0,ABS(H12)/F12*100) -> 12.159949 | K12: =F12/E12 -> 131.18651 | L12: =F12/D12 -> 30.247106 | M12: =$C$36*D12 -> 57604.972 | N12: =MAX(0,F12-M12) -> 33832.028 | O12: =IF(H12>0,"Over (di atas ideal)",IF(H12<0,"Under (di bawah ideal)","Tepat")) -> Over (di atas ideal)
A13: =Data!C13 -> 11 | B13: =Data!B13&" "&Data!A13 -> November 2024 | C13: =Data!D13 -> 23 | D13: =Data!E13 -> 3237 | E13: =Data!F13 -> 700 | F13: =Data!G13 -> 76332 | G13: =Regresi!$B$20+Regresi!$B$21*C13+Regresi!$B$22*D13+Regresi!$B$23*E13 -> 81757.752 | H13: =F13-G13 -> -5425.7522 | I13: =IF(G13=0,0,H13/G13*100) -> -6.6363765 | J13: =IF(F13=0,0,ABS(H13)/F13*100) -> 7.1080965 | K13: =F13/E13 -> 109.04571 | L13: =F13/D13 -> 23.581094 | M13: =$C$36*D13 -> 61682.862 | N13: =MAX(0,F13-M13) -> 14649.138 | O13: =IF(H13>0,"Over (di atas ideal)",IF(H13<0,"Under (di bawah ideal)","Tepat")) -> Under (di bawah ideal)
A14: =Data!C14 -> 12 | B14: =Data!B14&" "&Data!A14 -> December 2024 | C14: =Data!D14 -> 22 | D14: =Data!E14 -> 3014 | E14: =Data!F14 -> 699 | F14: =Data!G14 -> 62074 | G14: =Regresi!$B$20+Regresi!$B$21*C14+Regresi!$B$22*D14+Regresi!$B$23*E14 -> 76964.701 | H14: =F14-G14 -> -14890.701 | I14: =IF(G14=0,0,H14/G14*100) -> -19.347442 | J14: =IF(F14=0,0,ABS(H14)/F14*100) -> 23.988628 | K14: =F14/E14 -> 88.804006 | L14: =F14/D14 -> 20.595222 | M14: =$C$36*D14 -> 57433.471 | N14: =MAX(0,F14-M14) -> 4640.5285 | O14: =IF(H14>0,"Over (di atas ideal)",IF(H14<0,"Under (di bawah ideal)","Tepat")) -> Under (di bawah ideal)
... A26: =Data!C26 -> 24 | B26: =Data!B26&" "&Data!A26 -> December 2025 | C26: =Data!D26 -> 22 | D26: =Data!E26 -> 1998 | E26: =Data!F26 -> 729 | F26: =Data!G26 -> 29413 | G26: =Regresi!$B$20+Regresi!$B$21*C26+Regresi!$B$22*D26+Regresi!$B$23*E26 -> 44125.709 | H26: =F26-G26 -> -14712.709 | I26: =IF(G26=0,0,H26/G26*100) -> -33.342715 | J26: =IF(F26=0,0,ABS(H26)/F26*100) -> 50.021111 | K26: =F26/E26 -> 40.347051 | L26: =F26/D26 -> 14.721221 | M26: =$C$36*D26 -> 38073.018 | N26: =MAX(0,F26-M26) -> 0 | O26: =IF(H26>0,"Over (di atas ideal)",IF(H26<0,"Under (di bawah ideal)","Tepat")) -> Under (di bawah ideal)
A27: =Data!C27 -> 25 | B27: Januari | C27: =Data!D27 -> 20 | D27: =Data!E27 -> 2485 | E27: =Data!F27 -> 730 | F27: =Data!G27 -> 62983 | G27: =Regresi!$B$20+Regresi!$B$21*C27+Regresi!$B$22*D27+Regresi!$B$23*E27 -> 60678.615 | H27: =F27-G27 -> 2304.3853 | I27: =IF(G27=0,0,H27/G27*100) -> 3.7976894 | J27: =IF(F27=0,0,ABS(H27)/F27*100) -> 3.6587418 | K27: =F27/E27 -> 86.278082 | L27: =F27/D27 -> 25.345272 | M27: =$C$36*D27 -> 47353.078 | N27: =MAX(0,F27-M27) -> 15629.922 | O27: =IF(H27>0,"Over (di atas ideal)",IF(H27<0,"Under (di bawah ideal)","Tepat")) -> Over (di atas ideal)
A28: =Data!C28 -> 26 | B28: Februari | C28: =Data!D28 -> 20 | D28: =Data!E28 -> 2290 | E28: =Data!F28 -> 730 | F28: 58430 | G28: =Regresi!$B$20+Regresi!$B$21*C28+Regresi!$B$22*D28+Regresi!$B$23*E28 -> 55133.025 | H28: =F28-G28 -> 3296.9748 | I28: =IF(G28=0,0,H28/G28*100) -> 5.980036 | J28: =IF(F28=0,0,ABS(H28)/F28*100) -> 5.6426061 | K28: =F28/E28 -> 80.041096 | L28: =F28/D28 -> 25.515284 | M28: =$C$36*D28 -> 43637.243 | N28: =MAX(0,F28-M28) -> 14792.757 | O28: =IF(H28>0,"Over (di atas ideal)",IF(H28<0,"Under (di bawah ideal)","Tepat")) -> Over (di atas ideal)
A29: =Data!C29 -> 27 | B29: Maret | C29: =Data!D29 -> 19 | D29: =Data!E29 -> 2173 | E29: =Data!F29 -> 730 | F29: =Data!G29 -> 62758 | G29: =Regresi!$B$20+Regresi!$B$21*C29+Regresi!$B$22*D29+Regresi!$B$23*E29 -> 53222.998 | H29: =F29-G29 -> 9535.002 | I29: =IF(G29=0,0,H29/G29*100) -> 17.915191 | J29: =IF(F29=0,0,ABS(H29)/F29*100) -> 15.193285 | K29: =F29/E29 -> 85.969863 | L29: =F29/D29 -> 28.88081 | M29: =$C$36*D29 -> 41407.742 | N29: =MAX(0,F29-M29) -> 21350.258 | O29: =IF(H29>0,"Over (di atas ideal)",IF(H29<0,"Under (di bawah ideal)","Tepat")) -> Over (di atas ideal)
A30: =Data!C30 -> 28 | B30: April | C30: =Data!D30 -> 17 | D30: =Data!E30 -> 3283 | E30: =Data!F30 -> 730 | F30: 86773 | G30: =Regresi!$B$20+Regresi!$B$21*C30+Regresi!$B$22*D30+Regresi!$B$23*E30 -> 87624.852 | H30: =F30-G30 -> -851.8523 | I30: =IF(G30=0,0,H30/G30*100) -> -0.97215833 | J30: =IF(F30=0,0,ABS(H30)/F30*100) -> 0.98170203 | K30: =F30/E30 -> 118.86712 | L30: =F30/D30 -> 26.431008 | M30: =$C$36*D30 -> 62559.418 | N30: =MAX(0,F30-M30) -> 24213.582 | O30: =IF(H30>0,"Over (di atas ideal)",IF(H30<0,"Under (di bawah ideal)","Tepat")) -> Under (di bawah ideal)
A31: =Data!C31 -> 29 | B31: Mei | C31: =Data!D31 -> 21 | D31: =Data!E31 -> 2889 | E31: =Data!F31 -> 704 | F31: 84938 | G31: =Regresi!$B$20+Regresi!$B$21*C31+Regresi!$B$22*D31+Regresi!$B$23*E31 -> 74169.654 | H31: =F31-G31 -> 10768.346 | I31: =IF(G31=0,0,H31/G31*100) -> 14.518533 | J31: =IF(F31=0,0,ABS(H31)/F31*100) -> 12.677889 | K31: =F31/E31 -> 120.65057 | L31: =F31/D31 -> 29.400485 | M31: =$C$36*D31 -> 55051.526 | N31: =MAX(0,F31-M31) -> 29886.474 | O31: =IF(H31>0,"Over (di atas ideal)",IF(H31<0,"Under (di bawah ideal)","Tepat")) -> Over (di atas ideal)
A32: =Data!C32 -> 30 | B32: Juni | C32: =Data!D32 -> 20 | D32: =Data!E32 -> 3698 | E32: =Data!F32 -> 714 | F32: =Data!G32 -> 84449 | G32: =Regresi!$B$20+Regresi!$B$21*C32+Regresi!$B$22*D32+Regresi!$B$23*E32 -> 97279.051 | H32: =F32-G32 -> -12830.051 | I32: =IF(G32=0,0,H32/G32*100) -> -13.188915 | J32: =IF(F32=0,0,ABS(H32)/F32*100) -> 15.192662 | K32: =F32/E32 -> 118.27591 | L32: =F32/D32 -> 22.836398 | M32: =$C$36*D32 -> 70467.478 | N32: =MAX(0,F32-M32) -> 13981.522 | O32: =IF(H32>0,"Over (di atas ideal)",IF(H32<0,"Under (di bawah ideal)","Tepat")) -> Under (di bawah ideal)
A34: PARAMETER BENCHMARK (Index Ideal Normatif)
A35: Rasio OT/Volume rata-rata (kondisi saat ini) | C35: =AVERAGE(L3:L32) -> 24.525032
A36: Rasio OT/Volume efisien = kuartil 1 (25% terbaik) ← dasar Index Ideal Benchmark | C36: =QUARTILE(L3:L32,1) -> 19.055565
A37: Rasio OT/Man Power rata-rata | C37: =AVERAGE(K3:K32) -> 93.651672
A38: Rasio OT/Man Power efisien (kuartil 1) | C38: =QUARTILE(K3:K32,1) -> 76.138198
A39: Total Overtime Aktual (30 bulan) | C39: =SUM(F3:F32) -> 2058885
A40: Total Index Ideal Benchmark (30 bulan) | C40: =SUM(M3:M32) -> 1583841.4
A41: Total Potensi Penghematan Overtime | C41: =SUM(N3:N32) -> 510887.76
A42: % Potensi Penghematan terhadap Aktual | C42: =C41/C39*100 -> 24.813808
A43: MAPE model regresi (%) | C43: =AVERAGE(J3:J32) -> 17.024696
A44: Bulan dengan overtime paling boros (deviasi tertinggi) | C44: =INDEX(B3:B32,MATCH(MAX(H3:H32),H3:H32,0)) -> Januari 2024
A45: Bulan paling efisien (deviasi terendah) | C45: =INDEX(B3:B32,MATCH(MIN(H3:H32),H3:H32,0)) -> November 2025
A47: Definisi: (1) Index Ideal (Model) = nilai prediksi overtime dari persamaan regresi pada kondisi hari kerja, volume, dan man power bulan tsb — ini adalah level overtime yang WAJAR secara statistik. (2) Index Ideal Benchmark = volume bulan tsb x rasio OT/Volume kuartil-1 (25% bulan paling efisien) — ini adalah TARGET perbaikan. Selisih terhadap aktual = potensi penghematan.

Sheet Grafik
B2: Periode | C2: Indeks Aktual | D2: Indeks Ideal (Model Regresi)
B3: Januari | C3: 62983 | D3: 60678.615
B4: Februari | C4: 58430 | D4: 55133.025
B5: Maret | C5: 62758 | D5: 53222.998
B6: April | C6: 86773 | D6: 87624.852
B7: Mei | C7: 84938 | D7: 74169.654
B8: Juni | D8: 97279.051
B9: Juli | D9: 69943.303
B10: Agustus | D10: 64976.452
B11: September | D11: 81655.518
B12: Oktober | D12: 86286.443
B13: November | D13: 74683.363
B14: Desember | D14: 77930.02

Sheet Forecasting
A1: FORECASTING INDEX OVERTIME — Juli s.d Desember 2026
A2: Persamaan regresi tetap dari data training n=30 (Jan 2024 - Jun 2026). Isi sel kuning (X1, X2, X3) sesuai rencana/estimasi bulan berjalan — Index Ideal terhitung otomatis.
A3: Legend: | B3: Sel kuning = input Anda (X1, X2, X3) | E3: Sel hijau = hasil Index Ideal (formula, jangan diedit)
A5: t | B5: Periode | C5: Jumlah Hari Kerja (X1) | D5: Volume Produksi (X2) | E5: Total Man Power (X3) | F5: Index Ideal (Prediksi Overtime, Y) | G5: Index Ideal Benchmark (Efisien) | H5: Selisih Ideal vs Benchmark | J5: =23*60 -> 1380
A6: 31 | B6: Juli 2026 | C6: 23 | D6: 3714 | E6: 893 | F6: =Regresi!$B$20+Regresi!$B$21*C6+Regresi!$B$22*D6+Regresi!$B$23*E6 -> 69943.303 | G6: ='Index Ideal'!$C$36*D6 -> 70772.367 | H6: =F6-G6 -> -829.06408 | J6: =J5+38 -> 1418
A7: 32 | B7: Agustus 2026 | C7: 19 | D7: 3340 | E7: 893 | F7: =Regresi!$B$20+Regresi!$B$21*C7+Regresi!$B$22*D7+Regresi!$B$23*E7 -> 64976.452 | G7: ='Index Ideal'!$C$36*D7 -> 63645.586 | H7: =F7-G7 -> 1330.8667 | J7: =J6/4 -> 354.5
A8: 33 | B8: September 2026 | C8: 22 | D8: 4076 | E8: 893 | F8: =Regresi!$B$20+Regresi!$B$21*C8+Regresi!$B$22*D8+Regresi!$B$23*E8 -> 81655.518 | G8: ='Index Ideal'!$C$36*D8 -> 77670.481 | H8: =F8-G8 -> 3985.0371 | J8: =J7/60 -> 5.9083333
A9: 34 | B9: Oktober 2026 | C9: 21 | D9: 4189 | E9: 893 | F9: =Regresi!$B$20+Regresi!$B$21*C9+Regresi!$B$22*D9+Regresi!$B$23*E9 -> 86286.443 | G9: ='Index Ideal'!$C$36*D9 -> 79823.76 | H9: =F9-G9 -> 6462.6827
A10: 35 | B10: November 2026 | C10: 21 | D10: 3781 | E10: 893 | F10: =Regresi!$B$20+Regresi!$B$21*C10+Regresi!$B$22*D10+Regresi!$B$23*E10 -> 74683.363 | G10: ='Index Ideal'!$C$36*D10 -> 72049.089 | H10: =F10-G10 -> 2634.2736
A11: 36 | B11: Desember 2026 | C11: 22 | D11: 3945 | E11: 893 | F11: =Regresi!$B$20+Regresi!$B$21*C11+Regresi!$B$22*D11+Regresi!$B$23*E11 -> 77930.02 | G11: ='Index Ideal'!$C$36*D11 -> 75174.202 | H11: =F11-G11 -> 2755.8175
A13: Persamaan regresi yang dipakai (n=30, tidak berubah untuk semua bulan forecast):
A14: =Regresi!A42 -> Y = 114350,61667 + (-1417,32644 x X1) + (28,43892 x X2) + (-131,50163 x X3)
A16: Catatan:
A17: 1. t = indeks waktu lanjutan dari data training (t=1..30 = Jan 2024-Jun 2026). Juli 2026 = t=31, dst. t hanya nilai input X pada persamaan, bukan penambah n.
A18: 2. n training tetap 30 dan koefisien (b0..b3) di sheet Regresi TIDAK dihitung ulang selama forecast ini — model diestimasi sekali dari data aktual.
A19: 3. "Index Ideal (Model Regresi)" = level overtime yang wajar secara statistik untuk kombinasi X1, X2, X3 yang Anda input.
A20: 4. "Index Ideal Benchmark (Efisien)" = volume x rasio OT/Volume kuartil-1 (25% bulan paling efisien di data training) — target perbaikan, bukan prediksi model.
A21: 5. Jika nanti aktual bulan berjalan sudah tersedia, Anda boleh menambahkannya ke sheet Data dan re-estimasi model (n akan berubah jadi 31, 32, dst) — itu model baru, terpisah dari forecast ini.

Sheet Lead Closing
B2: Current | C2: menit | D2: Jam | F2: Actual | G2: menit | H2: Jam
B3: Weekly | C3: =5*60+15 -> 315 | D3: =C3/60 -> 5.25 | F3: Weekly | G3: =C3*70% -> 220.5 | H3: =G3/60 -> 3.675
B4: Monthly | C4: =C3*4 -> 1260 | D4: =C4/60 -> 21 | F4: Monthly | G4: =C4*70% -> 882 | H4: =G4/60 -> 14.7
